2019-02-16 23:40:47,217 ERROR: Exception on /user/Fabrigol [GET] [in c:\users\devinfab\appdata\local\programs\python\python37-32\microblog\venv\lib\site-packages\flask\app.py:1761]
Traceback (most recent call last):
  File "c:\users\devinfab\appdata\local\programs\python\python37-32\microblog\venv\lib\site-packages\flask\app.py", line 2292, in wsgi_app
    response = self.full_dispatch_request()
  File "c:\users\devinfab\appdata\local\programs\python\python37-32\microblog\venv\lib\site-packages\flask\app.py", line 1815, in full_dispatch_request
    rv = self.handle_user_exception(e)
  File "c:\users\devinfab\appdata\local\programs\python\python37-32\microblog\venv\lib\site-packages\flask\app.py", line 1718, in handle_user_exception
    reraise(exc_type, exc_value, tb)
  File "c:\users\devinfab\appdata\local\programs\python\python37-32\microblog\venv\lib\site-packages\flask\_compat.py", line 35, in reraise
    raise value
  File "c:\users\devinfab\appdata\local\programs\python\python37-32\microblog\venv\lib\site-packages\flask\app.py", line 1813, in full_dispatch_request
    rv = self.dispatch_request()
  File "c:\users\devinfab\appdata\local\programs\python\python37-32\microblog\venv\lib\site-packages\flask\app.py", line 1799, in dispatch_request
    return self.view_functions[rule.endpoint](**req.view_args)
  File "c:\users\devinfab\appdata\local\programs\python\python37-32\microblog\venv\lib\site-packages\flask_login\utils.py", line 261, in decorated_view
    return func(*args, **kwargs)
  File "C:\Users\devinfab\AppData\Local\Programs\Python\Python37-32\microblog\app\routes.py", line 79, in user
    return render_template('user.html', user=user, posts=posts)
  File "c:\users\devinfab\appdata\local\programs\python\python37-32\microblog\venv\lib\site-packages\flask\templating.py", line 134, in render_template
    return _render(ctx.app.jinja_env.get_or_select_template(template_name_or_list),
  File "c:\users\devinfab\appdata\local\programs\python\python37-32\microblog\venv\lib\site-packages\jinja2\environment.py", line 869, in get_or_select_template
    return self.get_template(template_name_or_list, parent, globals)
  File "c:\users\devinfab\appdata\local\programs\python\python37-32\microblog\venv\lib\site-packages\jinja2\environment.py", line 830, in get_template
    return self._load_template(name, self.make_globals(globals))
  File "c:\users\devinfab\appdata\local\programs\python\python37-32\microblog\venv\lib\site-packages\jinja2\environment.py", line 804, in _load_template
    template = self.loader.load(self, name, globals)
  File "c:\users\devinfab\appdata\local\programs\python\python37-32\microblog\venv\lib\site-packages\jinja2\loaders.py", line 125, in load
    code = environment.compile(source, name, filename)
  File "c:\users\devinfab\appdata\local\programs\python\python37-32\microblog\venv\lib\site-packages\jinja2\environment.py", line 591, in compile
    self.handle_exception(exc_info, source_hint=source_hint)
  File "c:\users\devinfab\appdata\local\programs\python\python37-32\microblog\venv\lib\site-packages\jinja2\environment.py", line 780, in handle_exception
    reraise(exc_type, exc_value, tb)
  File "c:\users\devinfab\appdata\local\programs\python\python37-32\microblog\venv\lib\site-packages\jinja2\_compat.py", line 37, in reraise
    raise value.with_traceback(tb)
  File "C:\Users\devinfab\AppData\Local\Programs\Python\Python37-32\microblog\app\templates\user.html", line 24, in template
    {% current_user.followed_posts().all() %}
  File "c:\users\devinfab\appdata\local\programs\python\python37-32\microblog\venv\lib\site-packages\jinja2\environment.py", line 497, in _parse
    return Parser(self, source, name, encode_filename(filename)).parse()
  File "c:\users\devinfab\appdata\local\programs\python\python37-32\microblog\venv\lib\site-packages\jinja2\parser.py", line 901, in parse
    result = nodes.Template(self.subparse(), lineno=1)
  File "c:\users\devinfab\appdata\local\programs\python\python37-32\microblog\venv\lib\site-packages\jinja2\parser.py", line 883, in subparse
    rv = self.parse_statement()
  File "c:\users\devinfab\appdata\local\programs\python\python37-32\microblog\venv\lib\site-packages\jinja2\parser.py", line 130, in parse_statement
    return getattr(self, 'parse_' + self.stream.current.value)()
  File "c:\users\devinfab\appdata\local\programs\python\python37-32\microblog\venv\lib\site-packages\jinja2\parser.py", line 268, in parse_block
    node.body = self.parse_statements(('name:endblock',), drop_needle=True)
  File "c:\users\devinfab\appdata\local\programs\python\python37-32\microblog\venv\lib\site-packages\jinja2\parser.py", line 165, in parse_statements
    result = self.subparse(end_tokens)
  File "c:\users\devinfab\appdata\local\programs\python\python37-32\microblog\venv\lib\site-packages\jinja2\parser.py", line 883, in subparse
    rv = self.parse_statement()
  File "c:\users\devinfab\appdata\local\programs\python\python37-32\microblog\venv\lib\site-packages\jinja2\parser.py", line 144, in parse_statement
    self.fail_unknown_tag(token.value, token.lineno)
  File "c:\users\devinfab\appdata\local\programs\python\python37-32\microblog\venv\lib\site-packages\jinja2\parser.py", line 97, in fail_unknown_tag
    return self._fail_ut_eof(name, self._end_token_stack, lineno)
  File "c:\users\devinfab\appdata\local\programs\python\python37-32\microblog\venv\lib\site-packages\jinja2\parser.py", line 90, in _fail_ut_eof
    self.fail(' '.join(message), lineno)
  File "c:\users\devinfab\appdata\local\programs\python\python37-32\microblog\venv\lib\site-packages\jinja2\parser.py", line 59, in fail
    raise exc(msg, lineno, self.name, self.filename)
jinja2.exceptions.TemplateSyntaxError: Encountered unknown tag 'current_user'. Jinja was looking for the following tags: 'endblock'. The innermost block that needs to be closed is 'block'.
2019-02-16 23:41:13,465 INFO: Microblog startup [in C:\Users\devinfab\AppData\Local\Programs\Python\Python37-32\microblog\app\__init__.py:42]
2019-02-17 21:20:20,503 INFO: Microblog startup [in C:\Users\devinfab\AppData\Local\Programs\Python\Python37-32\microblog\app\__init__.py:42]
2019-02-17 21:50:10,929 INFO: Microblog startup [in C:\Users\devinfab\AppData\Local\Programs\Python\Python37-32\microblog\app\__init__.py:42]
2019-02-17 21:50:30,139 ERROR: Exception on /index [POST] [in c:\users\devinfab\appdata\local\programs\python\python37-32\microblog\venv\lib\site-packages\flask\app.py:1761]
Traceback (most recent call last):
  File "c:\users\devinfab\appdata\local\programs\python\python37-32\microblog\venv\lib\site-packages\flask\app.py", line 2292, in wsgi_app
    response = self.full_dispatch_request()
  File "c:\users\devinfab\appdata\local\programs\python\python37-32\microblog\venv\lib\site-packages\flask\app.py", line 1815, in full_dispatch_request
    rv = self.handle_user_exception(e)
  File "c:\users\devinfab\appdata\local\programs\python\python37-32\microblog\venv\lib\site-packages\flask\app.py", line 1718, in handle_user_exception
    reraise(exc_type, exc_value, tb)
  File "c:\users\devinfab\appdata\local\programs\python\python37-32\microblog\venv\lib\site-packages\flask\_compat.py", line 35, in reraise
    raise value
  File "c:\users\devinfab\appdata\local\programs\python\python37-32\microblog\venv\lib\site-packages\flask\app.py", line 1813, in full_dispatch_request
    rv = self.dispatch_request()
  File "c:\users\devinfab\appdata\local\programs\python\python37-32\microblog\venv\lib\site-packages\flask\app.py", line 1799, in dispatch_request
    return self.view_functions[rule.endpoint](**req.view_args)
  File "c:\users\devinfab\appdata\local\programs\python\python37-32\microblog\venv\lib\site-packages\flask_login\utils.py", line 261, in decorated_view
    return func(*args, **kwargs)
  File "C:\Users\devinfab\AppData\Local\Programs\Python\Python37-32\microblog\app\routes.py", line 21, in index
    if form.validate_on_submit():
  File "c:\users\devinfab\appdata\local\programs\python\python37-32\microblog\venv\lib\site-packages\flask_wtf\form.py", line 101, in validate_on_submit
    return self.is_submitted() and self.validate()
  File "c:\users\devinfab\appdata\local\programs\python\python37-32\microblog\venv\lib\site-packages\wtforms\form.py", line 310, in validate
    return super(Form, self).validate(extra)
  File "c:\users\devinfab\appdata\local\programs\python\python37-32\microblog\venv\lib\site-packages\wtforms\form.py", line 152, in validate
    if not field.validate(self, extra):
  File "c:\users\devinfab\appdata\local\programs\python\python37-32\microblog\venv\lib\site-packages\wtforms\fields\core.py", line 206, in validate
    stop_validation = self._run_validation_chain(form, chain)
  File "c:\users\devinfab\appdata\local\programs\python\python37-32\microblog\venv\lib\site-packages\wtforms\fields\core.py", line 226, in _run_validation_chain
    validator(form, self)
  File "c:\users\devinfab\appdata\local\programs\python\python37-32\microblog\venv\lib\site-packages\wtforms\validators.py", line 95, in __call__
    if l < self.min or self.max != -1 and l > self.max:
TypeError: '<' not supported between instances of 'int' and 'str'
2019-02-17 21:52:39,675 INFO: Microblog startup [in C:\Users\devinfab\AppData\Local\Programs\Python\Python37-32\microblog\app\__init__.py:42]
2019-02-17 22:20:33,422 INFO: Microblog startup [in C:\Users\devinfab\AppData\Local\Programs\Python\Python37-32\microblog\app\__init__.py:42]
2019-02-17 22:45:02,370 INFO: Microblog startup [in C:\Users\devinfab\AppData\Local\Programs\Python\Python37-32\microblog\app\__init__.py:42]
2019-02-17 22:45:49,937 INFO: Microblog startup [in C:\Users\devinfab\AppData\Local\Programs\Python\Python37-32\microblog\app\__init__.py:42]
2019-02-22 19:28:59,585 INFO: Microblog startup [in /Users/fdevinar/microblog/app/__init__.py:42]
2019-02-22 19:49:02,179 INFO: Microblog startup [in /Users/fdevinar/microblog/app/__init__.py:42]
